Workbook

Sheet Base
A1: POD | B1: Puerto de descarga | C1: TT | D1: Carrier | E1: 20’ | F1: Gastos locales | G1: 40’ | H1: Gastos locales | I1: Validez
A2: Abu Dhabi - AEABD | C2: 65 | D2: MAERSK | E2: 750 | F2: $620,00 | G2: 950 | H2: $630,00 | I2: 45876
A3: Adelaide (AUADL) | C3: 66 | D3: MAERSK | E3: 1150 | F3: $620,00 | G3: 950 | H3: $630,00 | I3: 45876
A4: Agadir (MAAGA) | C4: 40 | D4: MAERSK | E4: 950 | F4: $620,00 | G4: 1000 | H4: $620,00 | I4: 45876
A5: Alexandria (EGALY) | C5: 50 | D5: MSC | E5: 3650 | F5: $620,00 | G5: 4800 | H5: $630,00 | I5: 45876
A6: Algeciras (ESALG) | C6: 30 | D6: CMA | E6: 1050 | F6: $620,00 | G6: 1250 | H6: $630,00 | I6: 45876
A7: Alger (DZALG) | C7: 57 | D7: HAPAG | E7: 1750 | F7: $620,00 | G7: 2050 | H7: $630,00 | I7: 45876
A8: Ambarli/Istambul - TRIST | C8: 54 | D8: HAPAG | E8: 1050 | F8: $620,00 | G8: 1450 | H8: $630,00 | I8: 45876
A9: Amsterdam (NLAMS) | B9: Rotterdam | C9: 31 | D9: MAERSK | E9: 1350 | F9: $620,00 | G9: 1450 | H9: $630,00 | I9: 45876
A10: Antwerp (BEANR) | C10: 47 | D10: HAPAG | E10: 1100 | F10: $620,00 | G10: 1150 | H10: $630,00 | I10: 45876
A11: Antwerp (BEANR) | C11: 36 | D11: MAERSK | E11: 1100 | F11: $620,00 | G11: 950 | H11: $630,00 | I11: 45876
A12: Apapa (NGAPP) | C12: 47 | D12: MSC | E12: 3350 | F12: $620,00 | G12: 4300 | H12: $630,00 | I12: 45876
A13: Aqaba - JOAQJ | C13: 62 | D13: MSC | E13: 3850 | F13: $620,00 | G13: 5850 | H13: $630,00 | I13: 45876
A14: Arica (CLARI) | C14: 40 | D14: MAERSK | E14: 3050 | F14: $620,00 | G14: 3350 | H14: $630,00 | I14: 45876
A15: Ashdod - ILASH | C15: 50 | D15: MAERSK | E15: 700 | F15: $620,00 | G15: 750 | H15: $630,00 | I15: 45876
A16: Atlanta (USATL) | B16: Charleston | C16: 42 | D16: CMA | E16: 4950 | F16: $620,00 | G16: 5100 | H16: $630,00 | I16: 45876
A17: Baltimore (USBAL) | C17: 37 | D17: CMA | E17: 4000 | F17: $620,00 | G17: 4400 | H17: $630,00 | I17: 45876
A18: Bangkok - THBKK | B18: Laem Chabang | C18: 47 | D18: MAERSK | E18: 1000 | F18: $620,00 | G18: 950 | H18: $630,00 | I18: 45876
A19: Barcelona (ESBCN) | C19: 32 | D19: MAERSK | E19: 1200 | F19: $620,00 | G19: 800 | H19: $630,00 | I19: 45876
A20: Baton Rouge (USBTR) | B20: New orleans | C20: 43 | D20: HAPAG | E20: 4300 | F20: $620,00 | G20: 4300 | H20: $630,00 | I20: 45876
A21: Beirut - LBBEY | C21: 53 | D21: HAPAG | E21: 2000 | F21: $620,00 | G21: 2300 | H21: $630,00 | I21: 45876
A22: Belfast | C22: 44 | D22: CMA | E22: 2250 | F22: 620 | G22: 2450 | H22: 630 | I22: 1/
A23: Bogota (COBOG) | C23: 30 | D23: MAERSK | E23: 4050 | F23: $620,00 | G23: 4350 | H23: $630,00 | I23: 45876
A24: Boston (USBOS) | C24: 60 | D24: MSC | E24: 4000 | F24: $620,00 | G24: 4850 | H24: $630,00 | I24: 45876
A25: Bremerhaven (DEBRV) | C25: 33 | D25: MAERSK | E25: 1100 | F25: $620,00 | G25: 950 | H25: $630,00 | I25: 45876
A26: Brisbane (AUBNE) | C26: 52 | D26: MAERSK | E26: 1400 | F26: $620,00 | G26: 1800 | H26: $630,00 | I26: 45876
A27: Bruselas (BEBRU) | B27: Antwerp | C27: 37 | D27: CMA | E27: 1800 | F27: $620,00 | G27: 2050 | H27: $630,00 | I27: 45876
A28: Budapest (HUBUD) | B28: Hamburgo | C28: 48 | D28: HAPAG | E28: 1850 | F28: $620,00 | G28: 3050 | H28: $630,00 | I28: 45876
A29: Budapest (HUBUD) | B29: Hamburgo | C29: 30 | D29: CMA | E29: NO | F29: $620,00 | G29: 2600 | H29: $630,00 | I29: 45876
A30: Busan, KR - KRPUS | C30: 48 | D30: MAERSK | E30: 950 | F30: $620,00 | G30: 900 | H30: $630,00 | I30: 45876
A31: Calgary (CACAL) | B31: Vancouver | C31: 72 | D31: CMA | E31: 5200 | F31: $620,00 | G31: 6700 | H31: $630,00 | I31: 45876
A32: Calgary (CACAL) | B32: Vancouver | C32: 62 | D32: MSC | E32: 5650 | F32: $620,00 | G32: 6100 | H32: $630,00 | I32: 45876
A33: Callao (PECLL) | C33: 24 | D33: HAPAG | E33: 2650 | F33: $620,00 | G33: 3050 | H33: $630,00 | I33: 45876
A34: Caracas (VECCS) | B34: La Guaira | C34: 35 | D34: MAERSK | E34: 3650 | F34: $620,00 | G34: 4200 | H34: $630,00 | I34: 45876
A35: Cartagena Port (COCTG) | C35: 25 | D35: MAERSK | E35: 2400 | F35: $620,00 | G35: 2700 | H35: $630,00 | I35: 45876
A36: Casablanca (MACAS) | C36: 55 | D36: HAPAG | E36: 1200 | F36: $620,00 | G36: 1650 | H36: $630,00 | I36: 45876
A37: Caucedo (DOCAU) | C37: 33 | D37: MAERSK | E37: 2550 | F37: $620,00 | G37: 2850 | H37: $630,00 | I37: 45876
A38: Charleston (USCHS) | C38: 42 | D38: CMA | E38: 4000 | F38: $620,00 | G38: 4150 | H38: $630,00 | I38: 45876
A39: Charlotte (USCLT) | B39: Charleston | C39: 42 | D39: CMA | E39: 5000 | F39: $620,00 | G39: 5050 | H39: $630,00 | I39: 45876
A40: Chicago (USCHI) | B40: New York | C40: 31 | D40: HAPAG | E40: 5050 | F40: $620,00 | G40: 5600 | H40: $630,00 | I40: 45876
...

Sheet Precios fletes
B1: Puerto de descarga | C1: TT | D1: Carrier | E1: 20’ | F1: 40’ | G1: Validez
A2: =Base!A2 -> Abu Dhabi - AEABD | B2: NA | C2: =Base!C2 -> 65 | D2: =Base!D2 -> MAERSK | E2: =SUM(Base!E2+1200) -> 1950 | F2: =SUM(Base!G2+1400) -> 2350 | G2: =Base!I2 -> 45876
A3: =Base!A3 -> Adelaide (AUADL) | B3: NA | C3: =Base!C3 -> 66 | D3: =Base!D3 -> MAERSK | E3: =SUM(Base!E3+1200) -> 2350 | F3: =SUM(Base!G3+1400) -> 2350 | G3: =Base!I3 -> 45876
A4: =Base!A4 -> Agadir (MAAGA) | B4: NA | C4: =Base!C4 -> 40 | D4: =Base!D4 -> MAERSK | E4: =SUM(Base!E4+1200) -> 2150 | F4: =SUM(Base!G4+1400) -> 2400 | G4: =Base!I4 -> 45876
A5: =Base!A5 -> Alexandria (EGALY) | B5: NA | C5: =Base!C5 -> 50 | D5: =Base!D5 -> MSC | E5: =SUM(Base!E5+1200) -> 4850 | F5: =SUM(Base!G5+1400) -> 6200 | G5: =Base!I5 -> 45876
A6: =Base!A6 -> Algeciras (ESALG) | B6: NA | C6: =Base!C6 -> 30 | D6: =Base!D6 -> CMA | E6: =SUM(Base!E6+1200) -> 2250 | F6: =SUM(Base!G6+1400) -> 2650 | G6: =Base!I6 -> 45876
A7: =Base!A7 -> Alger (DZALG) | B7: NA | C7: =Base!C7 -> 57 | D7: =Base!D7 -> HAPAG | E7: =SUM(Base!E7+1200) -> 2950 | F7: =SUM(Base!G7+1400) -> 3450 | G7: =Base!I7 -> 45876
A8: =Base!A8 -> Ambarli/Istambul - TRIST | B8: NA | C8: =Base!C8 -> 54 | D8: =Base!D8 -> HAPAG | E8: =SUM(Base!E8+1200) -> 2250 | F8: =SUM(Base!G8+1400) -> 2850 | G8: =Base!I8 -> 45876
A9: =Base!A9 -> Amsterdam (NLAMS) | B9: =Base!B9 -> Rotterdam | C9: =Base!C9 -> 31 | D9: =Base!D9 -> MAERSK | E9: =SUM(Base!E9+1200) -> 2550 | F9: =SUM(Base!G9+1400) -> 2850 | G9: =Base!I9 -> 45876
A10: =Base!A10 -> Antwerp (BEANR) | B10: NA | C10: =Base!C10 -> 47 | D10: =Base!D10 -> HAPAG | E10: =SUM(Base!E10+1200) -> 2300 | F10: =SUM(Base!G10+1400) -> 2550 | G10: =Base!I10 -> 45876
A11: =Base!A11 -> Antwerp (BEANR) | B11: NA | C11: =Base!C11 -> 36 | D11: =Base!D11 -> MAERSK | E11: =SUM(Base!E11+1200) -> 2300 | F11: =SUM(Base!G11+1400) -> 2350 | G11: =Base!I11 -> 45876
A12: =Base!A12 -> Apapa (NGAPP) | B12: NA | C12: =Base!C12 -> 47 | D12: =Base!D12 -> MSC | E12: =SUM(Base!E12+1200) -> 4550 | F12: =SUM(Base!G12+1400) -> 5700 | G12: =Base!I12 -> 45876
A13: =Base!A13 -> Aqaba - JOAQJ | B13: NA | C13: =Base!C13 -> 62 | D13: =Base!D13 -> MSC | E13: =SUM(Base!E13+1200) -> 5050 | F13: =SUM(Base!G13+1400) -> 7250 | G13: =Base!I13 -> 45876
A14: =Base!A14 -> Arica (CLARI) | B14: NA | C14: =Base!C14 -> 40 | D14: =Base!D14 -> MAERSK | E14: =SUM(Base!E14+1200) -> 4250 | F14: =SUM(Base!G14+1400) -> 4750 | G14: =Base!I14 -> 45876
A15: =Base!A15 -> Ashdod - ILASH | B15: NA | C15: =Base!C15 -> 50 | D15: =Base!D15 -> MAERSK | E15: =SUM(Base!E15+1200) -> 1900 | F15: =SUM(Base!G15+1400) -> 2150 | G15: =Base!I15 -> 45876
A16: =Base!A16 -> Atlanta (USATL) | B16: =Base!B16 -> Charleston | C16: =Base!C16 -> 42 | D16: =Base!D16 -> CMA | E16: =SUM(Base!E16+1200) -> 6150 | F16: =SUM(Base!G16+1400) -> 6500 | G16: =Base!I16 -> 45876
A17: =Base!A17 -> Baltimore (USBAL) | B17: NA | C17: =Base!C17 -> 37 | D17: =Base!D17 -> CMA | E17: =SUM(Base!E17+1200) -> 5200 | F17: =SUM(Base!G17+1400) -> 5800 | G17: =Base!I17 -> 45876
A18: =Base!A18 -> Bangkok - THBKK | B18: =Base!B18 -> Laem Chabang | C18: =Base!C18 -> 47 | D18: =Base!D18 -> MAERSK | E18: =SUM(Base!E18+1200) -> 2200 | F18: =SUM(Base!G18+1400) -> 2350 | G18: =Base!I18 -> 45876
A19: =Base!A19 -> Barcelona (ESBCN) | B19: NA | C19: =Base!C19 -> 32 | D19: =Base!D19 -> MAERSK | E19: =SUM(Base!E19+1200) -> 2400 | F19: =SUM(Base!G19+1400) -> 2200 | G19: =Base!I19 -> 45876
A20: =Base!A20 -> Baton Rouge (USBTR) | B20: =Base!B20 -> New orleans | C20: =Base!C20 -> 43 | D20: =Base!D20 -> HAPAG | E20: =SUM(Base!E20+1200) -> 5500 | F20: =SUM(Base!G20+1400) -> 5700 | G20: =Base!I20 -> 45876
A21: =Base!A21 -> Beirut - LBBEY | B21: NA | C21: =Base!C21 -> 53 | D21: =Base!D21 -> HAPAG | E21: =SUM(Base!E21+1200) -> 3200 | F21: =SUM(Base!G21+1400) -> 3700 | G21: =Base!I21 -> 45876
A22: =Base!A22 -> Belfast | B22: NA | C22: =Base!C22 -> 44 | D22: =Base!D22 -> CMA | E22: =SUM(Base!E22+1200) -> 3450 | F22: =SUM(Base!G22+1400) -> 3850 | G22: =Base!I22 -> 1/
A23: =Base!A23 -> Bogota (COBOG) | B23: NA | C23: =Base!C23 -> 30 | D23: =Base!D23 -> MAERSK | E23: =SUM(Base!E23+1200) -> 5250 | F23: =SUM(Base!G23+1400) -> 5750 | G23: =Base!I23 -> 45876
A24: =Base!A24 -> Boston (USBOS) | B24: NA | C24: =Base!C24 -> 60 | D24: =Base!D24 -> MSC | E24: =SUM(Base!E24+1200) -> 5200 | F24: =SUM(Base!G24+1400) -> 6250 | G24: =Base!I24 -> 45876
A25: =Base!A25 -> Bremerhaven (DEBRV) | B25: NA | C25: =Base!C25 -> 33 | D25: =Base!D25 -> MAERSK | E25: =SUM(Base!E25+1200) -> 2300 | F25: =SUM(Base!G25+1400) -> 2350 | G25: =Base!I25 -> 45876
A26: =Base!A26 -> Brisbane (AUBNE) | B26: NA | C26: =Base!C26 -> 52 | D26: =Base!D26 -> MAERSK | E26: =SUM(Base!E26+1200) -> 2600 | F26: =SUM(Base!G26+1400) -> 3200 | G26: =Base!I26 -> 45876
A27: =Base!A27 -> Bruselas (BEBRU) | B27: =Base!B27 -> Antwerp | C27: =Base!C27 -> 37 | D27: =Base!D27 -> CMA | E27: =SUM(Base!E27+1200) -> 3000 | F27: =SUM(Base!G27+1400) -> 3450 | G27: =Base!I27 -> 45876
A28: =Base!A28 -> Budapest (HUBUD) | B28: =Base!B28 -> Hamburgo | C28: =Base!C28 -> 48 | D28: =Base!D28 -> HAPAG | E28: =SUM(Base!E28+1200) -> 3050 | F28: =SUM(Base!G28+1400) -> 4450 | G28: =Base!I28 -> 45876
A29: =Base!A29 -> Budapest (HUBUD) | B29: =Base!B29 -> Hamburgo | C29: =Base!C29 -> 30 | D29: =Base!D29 -> CMA | F29: =SUM(Base!G29+1400) -> 4000 | G29: =Base!I29 -> 45876
A30: =Base!A30 -> Busan, KR - KRPUS | B30: NA | C30: =Base!C30 -> 48 | D30: =Base!D30 -> MAERSK | E30: =SUM(Base!E30+1200) -> 2150 | F30: =SUM(Base!G30+1400) -> 2300 | G30: =Base!I30 -> 45876
A31: =Base!A31 -> Calgary (CACAL) | B31: =Base!B31 -> Vancouver | C31: =Base!C31 -> 72 | D31: =Base!D31 -> CMA | E31: =SUM(Base!E31+1200) -> 6400 | F31: =SUM(Base!G31+1400) -> 8100 | G31: =Base!I31 -> 45876
A32: =Base!A32 -> Calgary (CACAL) | B32: =Base!B32 -> Vancouver | C32: =Base!C32 -> 62 | D32: =Base!D32 -> MSC | E32: =SUM(Base!E32+1200) -> 6850 | F32: =SUM(Base!G32+1400) -> 7500 | G32: =Base!I32 -> 45876
A33: =Base!A33 -> Callao (PECLL) | B33: NA | C33: =Base!C33 -> 24 | D33: =Base!D33 -> HAPAG | E33: =SUM(Base!E33+1200) -> 3850 | F33: =SUM(Base!G33+1400) -> 4450 | G33: =Base!I33 -> 45876
A34: =Base!A34 -> Caracas (VECCS) | B34: =Base!B34 -> La Guaira | C34: =Base!C34 -> 35 | D34: =Base!D34 -> MAERSK | E34: =SUM(Base!E34+1200) -> 4850 | F34: =SUM(Base!G34+1400) -> 5600 | G34: =Base!I34 -> 45876
A35: =Base!A35 -> Cartagena Port (COCTG) | B35: NA | C35: =Base!C35 -> 25 | D35: =Base!D35 -> MAERSK | E35: =SUM(Base!E35+1200) -> 3600 | F35: =SUM(Base!G35+1400) -> 4100 | G35: =Base!I35 -> 45876
A36: =Base!A36 -> Casablanca (MACAS) | B36: NA | C36: =Base!C36 -> 55 | D36: =Base!D36 -> HAPAG | E36: =SUM(Base!E36+1200) -> 2400 | F36: =SUM(Base!G36+1400) -> 3050 | G36: =Base!I36 -> 45876
A37: =Base!A37 -> Caucedo (DOCAU) | B37: NA | C37: =Base!C37 -> 33 | D37: =Base!D37 -> MAERSK | E37: =SUM(Base!E37+1200) -> 3750 | F37: =SUM(Base!G37+1400) -> 4250 | G37: =Base!I37 -> 45876
A38: =Base!A38 -> Charleston (USCHS) | B38: NA | C38: =Base!C38 -> 42 | D38: =Base!D38 -> CMA | E38: =SUM(Base!E38+1200) -> 5200 | F38: =SUM(Base!G38+1400) -> 5550 | G38: =Base!I38 -> 45876
A39: =Base!A39 -> Charlotte (USCLT) | B39: =Base!B39 -> Charleston | C39: =Base!C39 -> 42 | D39: =Base!D39 -> CMA | E39: =SUM(Base!E39+1200) -> 6200 | F39: =SUM(Base!G39+1400) -> 6450 | G39: =Base!I39 -> 45876
A40: =Base!A40 -> Chicago (USCHI) | B40: =Base!B40 -> New York | C40: =Base!C40 -> 31 | D40: =Base!D40 -> HAPAG | E40: =SUM(Base!E40+1200) -> 6250 | F40: =SUM(Base!G40+1400) -> 7000 | G40: =Base!I40 -> 45876
...
